<robot name="explorer_arm_description">
    <link name="base_link">
        
<inertial>
            <origin xyz="-1.14963978845132E-17 2.81283852810196E-16 -0.021" rpy="0 0 0" />
            <mass value="0.00457808589273548" />
            <inertia ixx="3.75944684702638E-07" ixy="-3.05505219716512E-22" ixz="1.91462529624083E-38" iyy="3.75944684702639E-07" iyz="2.29067520252043E-23" izz="7.48837312143454E-07" />
        </inertial>

        <visual>
            <origin xyz="0 0 0" rpy="0 0 0" />
            <geometry>
                <mesh filename="package://explorer_arm_description/meshes/base_link.STL" />
            </geometry>
            <material name="">
                <color rgba="0.898039215686275 0.917647058823529 0.929411764705882 1" />
            </material>
        </visual>
        <collision>
            <origin xyz="0 0 0" rpy="0 0 0" />
            <geometry>
                <mesh filename="package://explorer_arm_description/meshes/base_link.STL" />
            </geometry>
        </collision>
    </link>
    <link name="frame_link">
        
<inertial>
            <origin xyz="0.00559490486634598 0.00150970582414724 -0.00894794660551009" rpy="0 0 0" />
            <mass value="0.716022896559901" />
            <inertia ixx="0.000578336378382984" ixy="5.59588968848113E-06" ixz="0.000114049824805898" iyy="0.000767620726872662" iyz="1.12113576095402E-05" izz="0.000631424835005206" />
        </inertial>

        <visual>
            <origin xyz="0 0 0" rpy="0 0 0" />
            <geometry>
                <mesh filename="package://explorer_arm_description/meshes/frame_link.STL" />
            </geometry>
            <material name="">
                <color rgba="0.898039215686275 0.917647058823529 0.929411764705882 1" />
            </material>
        </visual>
        <collision>
            <origin xyz="0 0 0" rpy="0 0 0" />
            <geometry>
                <mesh filename="package://explorer_arm_description/meshes/frame_link.STL" />
            </geometry>
        </collision>
    </link>
    <joint name="arm1_bearing_joint" type="revolute">
        <origin xyz="0 0 -0.00445" rpy="3.1416 0 0" />
        <parent link="base_link" />
        <child link="frame_link" />
        <axis xyz="0 0 -1" />
        <limit lower="-3.14" upper="3.14" effort="0" velocity="0" />
    </joint>
    <link name="arm1_link">
        
<inertial>
            <origin xyz="-0.030256073197873 -0.218404437711336 -0.00678099233284524" rpy="0 0 0" />
            <mass value="0.479583183491115" />
            <inertia ixx="0.00882781622879315" ixy="-0.000187284179146167" ixz="6.10593439878394E-06" iyy="0.00044086181185441" iyz="-0.000436585425673148" izz="0.00890397904623876" />
        </inertial>

        <visual>
            <origin xyz="0 0 0" rpy="0 0 0" />
            <geometry>
                <mesh filename="package://explorer_arm_description/meshes/arm1_link.STL" />
            </geometry>
            <material name="">
                <color rgba="1 1 1 1" />
            </material>
        </visual>
        <collision>
            <origin xyz="0 0 0" rpy="0 0 0" />
            <geometry>
                <mesh filename="package://explorer_arm_description/meshes/arm1_link.STL" />
            </geometry>
        </collision>
    </link>
    <joint name="arm2_arm1_joint" type="revolute">
        <origin xyz="0.02825 0 -0.03945" rpy="0 0 0" />
        <parent link="frame_link" />
        <child link="arm1_link" />
        <axis xyz="1 0 0" />
        <limit lower="0" upper="3.14" effort="0" velocity="0" />
    </joint>
    <link name="arm2_link">
        
<inertial>
            <origin xyz="0.0230773036840093 0.149425363539173 0.000604367411549275" rpy="0 0 0" />
            <mass value="0.30183860324329" />
            <inertia ixx="0.00395332130818091" ixy="0.000223811751955492" ixz="9.29033202084006E-07" iyy="0.000127298943344165" iyz="-1.61739996059228E-05" izz="0.00399281590647534" />
        </inertial>

        <visual>
            <origin xyz="0 0 0" rpy="0 0 0" />
            <geometry>
                <mesh filename="package://explorer_arm_description/meshes/arm2_link.STL" />
            </geometry>
            <material name="">
                <color rgba="0.898039215686275 0.917647058823529 0.929411764705882 1" />
            </material>
        </visual>
        <collision>
            <origin xyz="0 0 0" rpy="0 0 0" />
            <geometry>
                <mesh filename="package://explorer_arm_description/meshes/arm2_link.STL" />
            </geometry>
        </collision>
    </link>
    <joint name="arm3_arm2_joint" type="revolute">
        <origin xyz="-0.039 -0.373 -0.065" rpy="0 0 0" />
        <parent link="arm1_link" />
        <child link="arm2_link" />
        <axis xyz="1 0 0" />
        <limit lower="-3.14" upper="0" effort="0" velocity="0" />
    </joint>
    <link name="arm3_link">
        
<inertial>
            <origin xyz="-0.00118377613278603 0.0127242561694025 -1.03698886144699E-08" rpy="0 0 0" />
            <mass value="0.0133110522817061" />
            <inertia ixx="2.66534640068597E-06" ixy="3.03729771047956E-07" ixz="5.3597822918578E-14" iyy="7.5510488466004E-06" iyz="-4.40040710512394E-14" izz="9.31485111150368E-06" />
        </inertial>

        <visual>
            <origin xyz="0 0 0" rpy="0 0 0" />
            <geometry>
                <mesh filename="package://explorer_arm_description/meshes/arm3_link.STL" />
            </geometry>
            <material name="">
                <color rgba="0.898039215686275 0.917647058823529 0.929411764705882 1" />
            </material>
        </visual>
        <collision>
            <origin xyz="0 0 0" rpy="0 0 0" />
            <geometry>
                <mesh filename="package://explorer_arm_description/meshes/arm3_link.STL" />
            </geometry>
        </collision>
    </link>
    <joint name="pt1_arm_joint" type="revolute">
        <origin xyz="0.017 0.29626 0.011099" rpy="0.0037086 1.0942E-15 1.7071E-16" />
        <parent link="arm2_link" />
        <child link="arm3_link" />
        <axis xyz="0 1 0" />
        <limit lower="-1.57" upper="1.57" effort="0" velocity="0" />
    </joint>
    <link name="pt1_link">
        
<inertial>
            <origin xyz="-0.0287860620577726 0.0198349840783305 0.0104187700658996" rpy="0 0 0" />
            <mass value="0.190957920799585" />
            <inertia ixx="0.000120203865437709" ixy="5.73630953543711E-06" ixz="3.14815226838004E-07" iyy="5.39172768700252E-05" iyz="-1.62075460996372E-06" izz="0.000102218995335893" />
        </inertial>

        <visual>
            <origin xyz="0 0 0" rpy="0 0 0" />
            <geometry>
                <mesh filename="package://explorer_arm_description/meshes/pt1_link.STL" />
            </geometry>
            <material name="">
                <color rgba="0.847058823529412 0.847058823529412 0.847058823529412 1" />
            </material>
        </visual>
        <collision>
            <origin xyz="0 0 0" rpy="0 0 0" />
            <geometry>
                <mesh filename="package://explorer_arm_description/meshes/pt1_link.STL" />
            </geometry>
        </collision>
    </link>
    <joint name="pt2_pt1_joint" type="revolute">
        <origin xyz="-0.026 0.032 0" rpy="-3.1416 1.3107E-15 -3.1416" />
        <parent link="arm3_link" />
        <child link="pt1_link" />
        <axis xyz="-1 0 0" />
        <limit lower="-0.84" upper="2.3" effort="0" velocity="0" />
    </joint>
    <link name="pt2_link">
        
<inertial>
            <origin xyz="1.81733767340431E-08 0.0284332582396072 0.00838368444932995" rpy="0 0 0" />
            <mass value="0.121273870412237" />
            <inertia ixx="5.33407624342047E-05" ixy="-3.21763614682469E-14" ixz="-9.75559373818246E-14" iyy="4.14185140311325E-05" iyz="2.67391767402412E-06" izz="3.25618639639074E-05" />
        </inertial>

        <visual>
            <origin xyz="0 0 0" rpy="0 0 0" />
            <geometry>
                <mesh filename="package://explorer_arm_description/meshes/pt2_link.STL" />
            </geometry>
            <material name="">
                <color rgba="1 1 1 1" />
            </material>
        </visual>
        <collision>
            <origin xyz="0 0 0" rpy="0 0 0" />
            <geometry>
                <mesh filename="package://explorer_arm_description/meshes/pt2_link.STL" />
            </geometry>
        </collision>
    </link>
    <joint name="rotate_joint" type="revolute">
        <origin xyz="-0.0303 0.0658 0.001" rpy="-1.053E-15 3.3847E-15 3.4383E-16" />
        <parent link="pt1_link" />
        <child link="pt2_link" />
        <axis xyz="0 1 0" />
        <limit lower="-1.57" upper="1.57" effort="0" velocity="0" />
    </joint>
    <link name="finger1_link">
        
<inertial>
            <origin xyz="-0.0100000082922938 -0.0505035464250828 3.62295665359558E-05" rpy="0 0 0" />
            <mass value="0.0145139008286365" />
            <inertia ixx="1.43204567924489E-05" ixy="1.30348121339267E-12" ixz="4.93976689182295E-13" iyy="1.17474129406709E-06" iyz="-2.51192020242968E-06" izz="1.40208598734018E-05" />
        </inertial>

        <visual>
            <origin xyz="0 0 0" rpy="0 0 0" />
            <geometry>
                <mesh filename="package://explorer_arm_description/meshes/finger1_link.STL" />
            </geometry>
            <material name="">
                <color rgba="0.752941176470588 0.752941176470588 0.752941176470588 1" />
            </material>
        </visual>
        <collision>
            <origin xyz="0 0 0" rpy="0 0 0" />
            <geometry>
                <mesh filename="package://explorer_arm_description/meshes/finger1_link.STL" />
            </geometry>
        </collision>
    </link>
    <joint name="finger1_finger2_joint" type="revolute">
        <origin xyz="0.028775 0.03635 0.02816" rpy="-2.4026E-15 -1.0472 -3.1416" />
        <parent link="pt2_link" />
        <child link="finger1_link" />
        <axis xyz="1 0 0" />
        <limit lower="-0.314" upper="0.1396" effort="0" velocity="0" />
    </joint>
    <link name="finger2_link">
        
<inertial>
            <origin xyz="-0.00999999999999877 -0.0491989260888196 -0.00026592383553746" rpy="0 0 0" />
            <mass value="0.0142516570501078" />
            <inertia ixx="1.29061026399682E-05" ixy="5.37630490293812E-22" ixz="4.25953225359251E-23" iyy="1.132832921293E-06" iyz="2.27545016132448E-06" izz="1.26481195573146E-05" />
        </inertial>

        <visual>
            <origin xyz="0 0 0" rpy="0 0 0" />
            <geometry>
                <mesh filename="package://explorer_arm_description/meshes/finger2_link.STL" />
            </geometry>
            <material name="">
                <color rgba="0.752941176470588 0.752941176470588 0.752941176470588 1" />
            </material>
        </visual>
        <collision>
            <origin xyz="0 0 0" rpy="0 0 0" />
            <geometry>
                <mesh filename="package://explorer_arm_description/meshes/finger2_link.STL" />
            </geometry>
        </collision>
    </link>
    <joint name="finger2_finger3_joint" type="revolute">
        <origin xyz="-0.01 0.03635 -0.039" rpy="-1.2013E-15 2.6737E-15 3.1416" />
        <parent link="pt2_link" />
        <child link="finger2_link" />
        <axis xyz="1 0 0" />
        <limit lower="-0.1396" upper="0.314" effort="0" velocity="0" />
    </joint>
    <link name="finger3_link">
        
<inertial>
            <origin xyz="-0.0100000102765049 -0.049198926110664 -0.000265918075369229" rpy="0 0 0" />
            <mass value="0.0142516570501078" />
            <inertia ixx="1.29061026399682E-05" ixy="-5.76772361617912E-21" ixz="3.30584024276525E-21" iyy="1.132832921293E-06" iyz="2.27545016132448E-06" izz="1.26481195573146E-05" />
        </inertial>

        <visual>
            <origin xyz="0 0 0" rpy="0 0 0" />
            <geometry>
                <mesh filename="package://explorer_arm_description/meshes/finger3_link.STL" />
            </geometry>
            <material name="">
                <color rgba="0.752941176470588 0.752941176470588 0.752941176470588 1" />
            </material>
        </visual>
        <collision>
            <origin xyz="0 0 0" rpy="0 0 0" />
            <geometry>
                <mesh filename="package://explorer_arm_description/meshes/finger3_link.STL" />
            </geometry>
        </collision>
    </link>
    <joint name="finger3_joint" type="revolute">
        <origin xyz="-0.028775 0.03635 0.02816" rpy="-3.1416 -1.0472 -2.3211E-15" />
        <parent link="pt2_link" />
        <child link="finger3_link" />
        <axis xyz="1 0 0" />
        <limit lower="-0.1396" upper="0.314" effort="0" velocity="0" />
    </joint>
    <link name="gripper_link"/>
    <joint name="gripper_joint" type="fixed">
        <origin xyz="0.08 0 0" rpy="0 0 0" />
        <parent link="pt2_link" />
        <child link="gripper_link" />
    </joint>
</robot>

