<robot
  name="explorer_sc_arm_description">
  <link
    name="base_link">
    <inertial>
      <origin
        xyz="8.38725949350256E-06 -0.002 2.2818279504248E-05"
        rpy="0 0 0" />
      <mass
        value="1.29696154829847" />
      <inertia
        ixx="0.00839947805440125"
        ixy="-6.97093840747434E-19"
        ixz="-4.27932542927772E-06"
        iyy="0.0277234800130074"
        iyz="1.39555161071416E-18"
        izz="0.0193274605227349" />
    </inertial>
    <visual>
      <origin
        xyz="0 0 0"
        rpy="0 0 0" />
      <geometry>
        <mesh
          filename="package://explorer_sc_arm_description/meshes/base_link.STL" />
      </geometry>
      <material
        name="">
        <color
          rgba="0.898039215686275 0.917647058823529 0.929411764705882 1" />
      </material>
    </visual>
    <collision>
      <origin
        xyz="0 0 0"
        rpy="0 0 0" />
      <geometry>
        <mesh
          filename="package://explorer_sc_arm_description/meshes/base_link.STL" />
      </geometry>
    </collision>
  </link>
  <link
    name="front_back_base">
    <inertial>
      <origin
        xyz="0 -3.46944695195361E-18 3.46944695195361E-18"
        rpy="0 0 0" />
      <mass
        value="0.098174770424681" />
      <inertia
        ixx="3.5792885050665E-05"
        ixy="0"
        ixz="1.6944868265256E-20"
        iyy="3.5792885050665E-05"
        iyz="-3.54804331259053E-23"
        izz="3.06796157577128E-05" />
    </inertial>
    <visual>
      <origin
        xyz="0 0 0"
        rpy="0 0 0" />
      <geometry>
        <mesh
          filename="package://explorer_sc_arm_description/meshes/front_back_base.STL" />
      </geometry>
      <material
        name="">
        <color
          rgba="0.752941176470588 0.752941176470588 0.752941176470588 1" />
      </material>
    </visual>
    <collision>
      <origin
        xyz="0 0 0"
        rpy="0 0 0" />
      <geometry>
        <mesh
          filename="package://explorer_sc_arm_description/meshes/front_back_base.STL" />
      </geometry>
    </collision>
  </link>
  <joint
    name="joint_front_back"
    type="fixed">
    <origin
      xyz="0.0244119960002226 0.00539021811108908 0.025"
      rpy="6.93889390390723E-18 -1.05100847812493E-16 1.5707963267949" />
    <parent
      link="base_link" />
    <child
      link="front_back_base" />
    <axis
      xyz="0 0 0" />
  </joint>
  <link
    name="left_up_wheel_link">
    <inertial>
      <origin
        xyz="-0.000972176276337972 0.000369232505078976 -7.64362320118672E-07"
        rpy="0 0 0" />
      <mass
        value="0.0699947504295786" />
      <inertia
        ixx="0.000151520374297291"
        ixy="9.3322150834294E-08"
        ixz="-1.86224874617693E-10"
        iyy="8.79982048344446E-05"
        iyz="-3.09477497923285E-09"
        izz="8.68322586693122E-05" />
    </inertial>
    <visual>
      <origin
        xyz="0 0 0"
        rpy="0 0 0" />
      <geometry>
        <mesh
          filename="package://explorer_sc_arm_description/meshes/left_up_wheel_link.STL" />
      </geometry>
      <material
        name="">
        <color
          rgba="1 1 0.949019607843137 1" />
      </material>
    </visual>
    <collision>
      <origin
        xyz="0 0 0"
        rpy="0 0 0" />
      <geometry>
        <mesh
          filename="package://explorer_sc_arm_description/meshes/left_up_wheel_link.STL" />
      </geometry>
    </collision>
  </link>
  <joint
    name="left_up_wheel_base_joint"
    type="revolute">
    <origin
      xyz="0.15861 -0.23931 -0.091104"
      rpy="-3.9302E-35 0 0" />
    <parent
      link="front_back_base" />
    <child
      link="left_up_wheel_link" />
    <axis
      xyz="-1 0 0" />
    <limit
      lower="-3.14"
      upper="3.14"
      effort="0"
      velocity="0" />
  </joint>
  <link
    name="right_up_wheel_link">
    <inertial>
      <origin
        xyz="0.001027823723661 0.000369232505078643 -7.6436232000765E-07"
        rpy="0 0 0" />
      <mass
        value="0.0699947504295802" />
      <inertia
        ixx="0.000151520374297294"
        ixy="9.33221508338905E-08"
        ixz="-1.86224874585881E-10"
        iyy="8.7998204834447E-05"
        iyz="-3.09477497912329E-09"
        izz="8.68322586693145E-05" />
    </inertial>
    <visual>
      <origin
        xyz="0 0 0"
        rpy="0 0 0" />
      <geometry>
        <mesh
          filename="package://explorer_sc_arm_description/meshes/right_up_wheel_link.STL" />
      </geometry>
      <material
        name="">
        <color
          rgba="1 1 0.949019607843137 1" />
      </material>
    </visual>
    <collision>
      <origin
        xyz="0 0 0"
        rpy="0 0 0" />
      <geometry>
        <mesh
          filename="package://explorer_sc_arm_description/meshes/right_up_wheel_link.STL" />
      </geometry>
    </collision>
  </link>
  <joint
    name="right_up_wheel_base_joint"
    type="revolute">
    <origin
      xyz="-0.16939 -0.23931 -0.091104"
      rpy="-3.9302E-35 0 0" />
    <parent
      link="front_back_base" />
    <child
      link="right_up_wheel_link" />
    <axis
      xyz="-1 0 0" />
    <limit
      lower="-3.14"
      upper="3.14"
      effort="0"
      velocity="0" />
  </joint>
  <link
    name="left_down_wheel_link">
    <inertial>
      <origin
        xyz="-0.000972173827561984 0.000364057332673751 -6.16251453142702E-05"
        rpy="0 0 0" />
      <mass
        value="0.0699947445973927" />
      <inertia
        ixx="0.000151520357123179"
        ixy="9.20202650564586E-08"
        ixz="-1.55694653153588E-08"
        iyy="8.79654970741046E-05"
        iyz="-1.92511615410959E-07"
        izz="8.68649398356746E-05" />
    </inertial>
    <visual>
      <origin
        xyz="0 0 0"
        rpy="0 0 0" />
      <geometry>
        <mesh
          filename="package://explorer_sc_arm_description/meshes/left_down_wheel_link.STL" />
      </geometry>
      <material
        name="">
        <color
          rgba="1 1 0.949019607843137 1" />
      </material>
    </visual>
    <collision>
      <origin
        xyz="0 0 0"
        rpy="0 0 0" />
      <geometry>
        <mesh
          filename="package://explorer_sc_arm_description/meshes/left_down_wheel_link.STL" />
      </geometry>
    </collision>
  </link>
  <joint
    name="left_down_wheel_base_joint"
    type="revolute">
    <origin
      xyz="0.15861 0.28813 -0.091104"
      rpy="-7.0265E-33 1.1082E-16 -6.5165E-17" />
    <parent
      link="front_back_base" />
    <child
      link="left_down_wheel_link" />
    <axis
      xyz="-1 0 0" />
    <limit
      lower="-3.14"
      upper="3.14"
      effort="0"
      velocity="0" />
  </joint>
  <link
    name="right_down_wheel_link">
    <inertial>
      <origin
        xyz="0.00102782372366148 0.000364054428132365 -6.16246737445564E-05"
        rpy="0 0 0" />
      <mass
        value="0.0699947504295788" />
      <inertia
        ixx="0.000151520374297291"
        ixy="9.20145592386898E-08"
        ixz="-1.55685389218621E-08"
        iyy="8.79655102994899E-05"
        iyz="-1.9251159099689E-07"
        izz="8.6864953204268E-05" />
    </inertial>
    <visual>
      <origin
        xyz="0 0 0"
        rpy="0 0 0" />
      <geometry>
        <mesh
          filename="package://explorer_sc_arm_description/meshes/right_down_wheel_link.STL" />
      </geometry>
      <material
        name="">
        <color
          rgba="1 1 0.949019607843137 1" />
      </material>
    </visual>
    <collision>
      <origin
        xyz="0 0 0"
        rpy="0 0 0" />
      <geometry>
        <mesh
          filename="package://explorer_sc_arm_description/meshes/right_down_wheel_link.STL" />
      </geometry>
    </collision>
  </link>
  <joint
    name="right_down_wheel_base_joint"
    type="revolute">
    <origin
      xyz="-0.16939 0.28813 -0.091104"
      rpy="-7.0265E-33 1.1082E-16 -6.5165E-17" />
    <parent
      link="front_back_base" />
    <child
      link="right_down_wheel_link" />
    <axis
      xyz="-1 0 0" />
    <limit
      lower="-3.14"
      upper="3.14"
      effort="0"
      velocity="0" />
  </joint>
  <link
    name="frame_link">
    <inertial>
      <origin
        xyz="-0.00576465576784417 0.0185782179192016 0.0214107538459015"
        rpy="0 0 0" />
      <mass
        value="1.7992512190132" />
      <inertia
        ixx="0.0405328064710785"
        ixy="-0.000346818500403772"
        ixz="1.29513681508136E-05"
        iyy="0.0217532006079323"
        iyz="0.000217060440161705"
        izz="0.0573134555077923" />
    </inertial>
    <visual>
      <origin
        xyz="0 0 0"
        rpy="0 0 0" />
      <geometry>
        <mesh
          filename="package://explorer_sc_arm_description/meshes/frame_link.STL" />
      </geometry>
      <material
        name="">
        <color
          rgba="1 1 1 1" />
      </material>
    </visual>
    <collision>
      <origin
        xyz="0 0 0"
        rpy="0 0 0" />
      <geometry>
        <mesh
          filename="package://explorer_sc_arm_description/meshes/frame_link.STL" />
      </geometry>
    </collision>
  </link>
  <joint
    name="robot_left_right"
    type="fixed">
    <origin
      xyz="0 0 0"
      rpy="-3.93023761073179E-35 0 0" />
    <parent
      link="front_back_base" />
    <child
      link="frame_link" />
    <axis
      xyz="0 0 0" />
  </joint>
  <link
    name="arm1_link">
    <inertial>
      <origin
        xyz="0.00573187427866573 -0.0015980808869738 0.0293671674418244"
        rpy="0 0 0" />
      <mass
        value="0.676426297298435" />
      <inertia
        ixx="0.000616794693273129"
        ixy="-5.74395142307882E-06"
        ixz="-0.000114502676819043"
        iyy="0.000803913163230778"
        iyz="1.24337117219628E-05"
        izz="0.000640131746001396" />
    </inertial>
    <visual>
      <origin
        xyz="0 0 0"
        rpy="0 0 0" />
      <geometry>
        <mesh
          filename="package://explorer_sc_arm_description/meshes/arm1_link.STL" />
      </geometry>
      <material
        name="">
        <color
          rgba="0.6 0.6 0.6 1" />
      </material>
    </visual>
    <collision>
      <origin
        xyz="0 0 0"
        rpy="0 0 0" />
      <geometry>
        <mesh
          filename="package://explorer_sc_arm_description/meshes/arm1_link.STL" />
      </geometry>
    </collision>
  </link>
  <joint
    name="arm1_bearing_joint"
    type="revolute">
    <origin
      xyz="0.06261 -0.045588 0.045"
      rpy="-3.9302E-35 0 0" />
    <parent
      link="frame_link" />
    <child
      link="arm1_link" />
    <axis
      xyz="0 0 1" />
    <limit
      lower="-1.57"
      upper="1.57"
      effort="0"
      velocity="0" />
  </joint>
  <link
    name="arm2_link">
    <inertial>
      <origin
        xyz="-0.0236231576683058 0.22295004458353 0.0112847556280396"
        rpy="0 0 0" />
      <mass
        value="0.196076424497199" />
      <inertia
        ixx="0.00367815543806653"
        ixy="-8.85335103532249E-06"
        ixz="-9.50547616828603E-07"
        iyy="0.00018223490274496"
        iyz="-0.000332537237265352"
        izz="0.00360490309941874" />
    </inertial>
    <visual>
      <origin
        xyz="0 0 0"
        rpy="0 0 0" />
      <geometry>
        <mesh
          filename="package://explorer_sc_arm_description/meshes/arm2_link.STL" />
      </geometry>
      <material
        name="">
        <color
          rgba="0.752941176470588 0.752941176470588 0.752941176470588 1" />
      </material>
    </visual>
    <collision>
      <origin
        xyz="0 0 0"
        rpy="0 0 0" />
      <geometry>
        <mesh
          filename="package://explorer_sc_arm_description/meshes/arm2_link.STL" />
      </geometry>
    </collision>
  </link>
  <joint
    name="arm2_arm1_joint"
    type="revolute">
    <origin
      xyz="0.02425 0 0.061"
      rpy="-6.9389E-18 1.6633E-16 3.3897E-15" />
    <parent
      link="arm1_link" />
    <child
      link="arm2_link" />
    <axis
      xyz="-1 0 0" />
    <limit
      lower="-2.16"
      upper="0"
      effort="0"
      velocity="0" />
  </joint>
  <link
    name="arm3_link">
    <inertial>
      <origin
        xyz="0.000523917843228638 -0.186356285755502 -0.000729012337332191"
        rpy="0 0 0" />
      <mass
        value="0.208381103991094" />
      <inertia
        ixx="0.00226355266229584"
        ixy="-1.60730065149407E-05"
        ixz="-7.54891528572832E-08"
        iyy="6.45224144489488E-05"
        iyz="-8.7514133087201E-06"
        izz="0.00226397281371866" />
    </inertial>
    <visual>
      <origin
        xyz="0 0 0"
        rpy="0 0 0" />
      <geometry>
        <mesh
          filename="package://explorer_sc_arm_description/meshes/arm3_link.STL" />
      </geometry>
      <material
        name="">
        <color
          rgba="0.752941176470588 0.752941176470588 0.752941176470588 1" />
      </material>
    </visual>
    <collision>
      <origin
        xyz="0 0 0"
        rpy="0 0 0" />
      <geometry>
        <mesh
          filename="package://explorer_sc_arm_description/meshes/arm3_link.STL" />
      </geometry>
    </collision>
  </link>
  <joint
    name="arm3_arm2_joint"
    type="revolute">
    <origin
      xyz="-0.0175 0.37413 0.065"
      rpy="0 0 0" />
    <parent
      link="arm2_link" />
    <child
      link="arm3_link" />
    <axis
      xyz="-1 0 0" />
    <limit
      lower="0"
      upper="3.14"
      effort="0"
      velocity="0" />
  </joint>
  <link
    name="pt1_link">
    <inertial>
      <origin
        xyz="-1.38777878078145E-17 -0.0101240439715932 5.55111512312578E-17"
        rpy="0 0 0" />
      <mass
        value="0.0133110522817061" />
      <inertia
        ixx="2.50594470944606E-06"
        ixy="1.85303136769406E-20"
        ixz="6.92418866817431E-20"
        iyy="7.195366856988E-06"
        iyz="4.59250676089427E-21"
        izz="8.79976743065138E-06" />
    </inertial>
    <visual>
      <origin
        xyz="0 0 0"
        rpy="0 0 0" />
      <geometry>
        <mesh
          filename="package://explorer_sc_arm_description/meshes/pt1_link.STL" />
      </geometry>
      <material
        name="">
        <color
          rgba="0.752941176470588 0.752941176470588 0.752941176470588 1" />
      </material>
    </visual>
    <collision>
      <origin
        xyz="0 0 0"
        rpy="0 0 0" />
      <geometry>
        <mesh
          filename="package://explorer_sc_arm_description/meshes/pt1_link.STL" />
      </geometry>
    </collision>
  </link>
  <joint
    name="pt1_arm_joint"
    type="revolute">
    <origin
      xyz="-0.0005 -0.29839 -0.011103"
      rpy="0.0037086 1.6759E-15 -2.5288E-16" />
    <parent
      link="arm3_link" />
    <child
      link="pt1_link" />
    <axis
      xyz="0 -1 0" />
    <limit
      lower="-1.72"
      upper="1.42"
      effort="0"
      velocity="0" />
  </joint>
  <link
    name="pt2_link">
    <inertial>
      <origin
        xyz="0.0284666409378878 -0.012296524956937 0.0208881619219743"
        rpy="0 0 0" />
      <mass
        value="0.222075702540908" />
      <inertia
        ixx="0.000448658968824594"
        ixy="3.74295966975417E-06"
        ixz="-3.76370485964757E-06"
        iyy="0.000237172522813216"
        iyz="-0.000148614817626506"
        izz="0.000251351686770739" />
    </inertial>
    <visual>
      <origin
        xyz="0 0 0"
        rpy="0 0 0" />
      <geometry>
        <mesh
          filename="package://explorer_sc_arm_description/meshes/pt2_link.STL" />
      </geometry>
      <material
        name="">
        <color
          rgba="0.752941176470588 0.752941176470588 0.752941176470588 1" />
      </material>
    </visual>
    <collision>
      <origin
        xyz="0 0 0"
        rpy="0 0 0" />
      <geometry>
        <mesh
          filename="package://explorer_sc_arm_description/meshes/pt2_link.STL" />
      </geometry>
    </collision>
  </link>
  <joint
    name="pt2_pt1_joint"
    type="revolute">
    <origin
      xyz="-0.02555 -0.031 0"
      rpy="-1.0528E-14 1.3913E-14 2.3915E-17" />
    <parent
      link="pt1_link" />
    <child
      link="pt2_link" />
    <axis
      xyz="-1 0 0" />
    <limit
      lower="-1.81"
      upper="0.3"
      effort="0"
      velocity="0" />
  </joint>
  <link
    name="gripper_rotate_link">
    <inertial>
      <origin
        xyz="-8.56406842225654E-06 -0.033251813169419 0.0078139226958282"
        rpy="0 0 0" />
      <mass
        value="0.126580619621662" />
      <inertia
        ixx="7.83741507963795E-05"
        ixy="-4.70272447047726E-08"
        ixz="-1.20878400844121E-08"
        iyy="4.26849732289127E-05"
        iyz="-6.47305761247514E-06"
        izz="5.78578684503002E-05" />
    </inertial>
    <visual>
      <origin
        xyz="0 0 0"
        rpy="0 0 0" />
      <geometry>
        <mesh
          filename="package://explorer_sc_arm_description/meshes/gripper_rotate_link.STL" />
      </geometry>
      <material
        name="">
        <color
          rgba="1 1 1 1" />
      </material>
    </visual>
    <collision>
      <origin
        xyz="0 0 0"
        rpy="0 0 0" />
      <geometry>
        <mesh
          filename="package://explorer_sc_arm_description/meshes/gripper_rotate_link.STL" />
      </geometry>
    </collision>
  </link>
  <joint
    name="rotate_joint"
    type="revolute">
    <origin
      xyz="0.02985 -0.06535 0.001"
      rpy="1.0648E-14 -3.4915E-15 -3.4915E-15" />
    <parent
      link="pt2_link" />
    <child
      link="gripper_rotate_link" />
    <axis
      xyz="0 -1 0" />
    <limit
      lower="-1.57"
      upper="1.57"
      effort="0"
      velocity="0" />
  </joint>
  <link
    name="finger1_link">
    <inertial>
      <origin
        xyz="1.12793552276003E-10 -0.0489586901331791 0.00032819327194647"
        rpy="0 0 0" />
      <mass
        value="0.0141817215051188" />
      <inertia
        ixx="1.27275057009475E-05"
        ixy="6.40870855165778E-14"
        ixz="-3.60667593287892E-13"
        iyy="1.1215488667079E-06"
        iyz="-2.23221813422534E-06"
        izz="1.2480727742978E-05" />
    </inertial>
    <visual>
      <origin
        xyz="0 0 0"
        rpy="0 0 0" />
      <geometry>
        <mesh
          filename="package://explorer_sc_arm_description/meshes/finger1_link.STL" />
      </geometry>
      <material
        name="">
        <color
          rgba="0.6 0.6 0.6 1" />
      </material>
    </visual>
    <collision>
      <origin
        xyz="0 0 0"
        rpy="0 0 0" />
      <geometry>
        <mesh
          filename="package://explorer_sc_arm_description/meshes/finger1_link.STL" />
      </geometry>
    </collision>
  </link>
  <joint
    name="finger1_joint"
    type="revolute">
    <origin
      xyz="-0.033775 -0.0368 0.0195"
      rpy="3.4556E-30 -1.0472 -4.3437E-19" />
    <parent
      link="gripper_rotate_link" />
    <child
      link="finger1_link" />
    <axis
      xyz="1 0 0" />
    <limit
      lower="-0.314"
      upper="0.1396"
      effort="0"
      velocity="0" />
  </joint>
  <link
    name="finger2_link">
    <inertial>
      <origin
        xyz="1.38777878078145E-17 -0.0491989260888198 0.000265923835535448"
        rpy="0 0 0" />
      <mass
        value="0.0142516570501078" />
      <inertia
        ixx="1.29061026399681E-05"
        ixy="-5.52830919409279E-22"
        ixz="5.65460853796141E-22"
        iyy="1.13283292129298E-06"
        iyz="-2.27545016132449E-06"
        izz="1.26481195573146E-05" />
    </inertial>
    <visual>
      <origin
        xyz="0 0 0"
        rpy="0 0 0" />
      <geometry>
        <mesh
          filename="package://explorer_sc_arm_description/meshes/finger2_link.STL" />
      </geometry>
      <material
        name="">
        <color
          rgba="0.6 0.6 0.6 1" />
      </material>
    </visual>
    <collision>
      <origin
        xyz="0 0 0"
        rpy="0 0 0" />
      <geometry>
        <mesh
          filename="package://explorer_sc_arm_description/meshes/finger2_link.STL" />
      </geometry>
    </collision>
  </link>
  <joint
    name="finger2_joint"
    type="revolute">
    <origin
      xyz="0 -0.0368 -0.039"
      rpy="3.1416 -1.5777E-30 -3.1416" />
    <parent
      link="gripper_rotate_link" />
    <child
      link="finger2_link" />
    <axis
      xyz="1 0 0" />
    <limit
      lower="-0.314"
      upper="0.1396"
      effort="0"
      velocity="0" />
  </joint>
  <link
    name="finger3_link">
    <inertial>
      <origin
        xyz="4.16333634234434E-17 -0.0491989260888198 0.000265923835535337"
        rpy="0 0 0" />
      <mass
        value="0.0142516570501078" />
      <inertia
        ixx="1.29061026399682E-05"
        ixy="3.09741571954594E-21"
        ixz="3.3881317890172E-21"
        iyy="1.13283292129301E-06"
        iyz="-2.27545016132449E-06"
        izz="1.26481195573146E-05" />
    </inertial>
    <visual>
      <origin
        xyz="0 0 0"
        rpy="0 0 0" />
      <geometry>
        <mesh
          filename="package://explorer_sc_arm_description/meshes/finger3_link.STL" />
      </geometry>
      <material
        name="">
        <color
          rgba="0.6 0.6 0.6 1" />
      </material>
    </visual>
    <collision>
      <origin
        xyz="0 0 0"
        rpy="0 0 0" />
      <geometry>
        <mesh
          filename="package://explorer_sc_arm_description/meshes/finger3_link.STL" />
      </geometry>
    </collision>
  </link>
  <joint
    name="finger3_joint"
    type="revolute">
    <origin
      xyz="0.033775 -0.0368 0.0195"
      rpy="3.4556E-30 1.0472 4.33E-19" />
    <parent
      link="gripper_rotate_link" />
    <child
      link="finger3_link" />
    <axis
      xyz="-1 0 0" />
    <limit
      lower="-0.1396"
      upper="0.314"
      effort="0"
      velocity="0" />
  </joint>
  <link name="gripper_link"/>
  <joint 
    name="gripper_joint" 
    type="fixed">
    <origin 
      xyz="0.08 0 0" 
      rpy="0 0 0" />
    <parent 
      link="gripper_rotate_link" />
    <child 
      link="gripper_link" />
  </joint>
</robot>
